Workbook
Name _10ports: #REF!
Name _10ports: #REF!
Name _12ports: #REF!
Name _12ports: #REF!
Name _14ports: #REF!
Name _14ports: #REF!
Name _16ports: #REF!
Name _16ports: #REF!
Name _1port: #REF!
Name _1port: #REF!
Name _2ports: #REF!
Name _2ports: #REF!
Name _4ports: #REF!
Name _4ports: #REF!
Name _6ports: #REF!
Name _6ports: #REF!
Name _8ports: #REF!
Name _8ports: #REF!
Name Additional_lessor_requirements_others: #REF!
Name Additional_lessor_requirements_others: #REF!
Name Additional_lessor_requirements_others: #REF!
Name Additional_lessor_requirements_others: #REF!
Name Additional_lessor_requirements_others: #REF!
Name Additional_lessor_requirements_others: #REF!
Name Additional_lessor_requirements_others: #REF!
Name Additional_lessor_requirements_others: #REF!
Name Additional_lessor_requirements_others: #REF!
Name Additional_lessor_requirements_others: #REF!
Name Additional_lessor_requirements_others: #REF!
Name Additional_lessor_requirements_others: #REF!
Name Additional_lessor_requirements_others: #REF!
Name Additional_lessor_requirements_others: #REF!
Name Additional_lessor_requirements_others: #REF!
Name Additional_lessor_requirements_others: #REF!
Name AMBSOLUTION: [1]Conditions!$E$1:$E$13
Name AMBSOLUTION: [1]Conditions!$E$1:$E$13
Name AMBSOLUTION: [1]Conditions!$E$1:$E$13
Name AMBSOLUTION: [1]Conditions!$E$1:$E$13
Name AMBSOLUTION: [2]Conditions!$E$1:$E$13
Name ANTENNASHARING: [1]Conditions!$B$2:$B$60
Name ANTENNASHARING: [1]Conditions!$B$2:$B$60
Name ANTENNASHARING: [1]Conditions!$B$2:$B$60
Name ANTENNASHARING: [1]Conditions!$B$2:$B$60
Name ANTENNASHARING: [2]Conditions!$B$2:$B$60
Name ANTENNASPECS: [1]Conditions!$C$1:$C$13
Name ANTENNASPECS: [1]Conditions!$C$1:$C$13
Name ANTENNASPECS: [1]Conditions!$C$1:$C$13
Name ANTENNASPECS: [1]Conditions!$C$1:$C$13
Name ANTENNASPECS: [2]Conditions!$C$1:$C$13
Name ANTENNATYPE: [1]Conditions!$A$1:$A$35
Name ANTENNATYPE: [1]Conditions!$A$1:$A$35
Name ANTENNATYPE: [1]Conditions!$A$1:$A$35
Name ANTENNATYPE: [1]Conditions!$A$1:$A$35
Name ANTENNATYPE: [2]Conditions!$A$1:$A$35
Name BrandandModel58: #REF!
Name BrandandModel58: #REF!
Name BrandandModel58: #REF!
Name BrandandModel58: #REF!
Name BrandandModel58: #REF!
Name BrandandModel58: #REF!

Sheet Summary of TSSR Details
A1: 1. Site Information Details
A3: Section | B3: Section Title | C3: Use for OLT Assessment
A4: A.1 | B4: Basic Site Information | C4: Confirm site ownership, site type, grid condition, access, flood history, hauling remarks, work permit, security, and vehicle accessibility.
A5: A.2 | B5: Site Location Description | C5: Check site location, access limitations, obstructions, and site defects that may affect OLT & transport implementation.
A6: D.1 | B6: Outdoor Photos | C6: Validate available ground/site space, access path, obstructions, cabinet area, and general site condition.
A8: The sample DIGITAL TSSR already includes A.1, A.3 and D.1 as part of the approved report sections
A10: 2. Space and physical installation survey Details
A12: Section | B12: Section Title | C12: Use for OLT Assessment
A13: D.4 | B13: Cabinet and Rack Information | C13: Main reference for available rack/cabinet space for OLT, transport, rectifier, PDU/DCDU, or auxiliary equipment. Check existing equipment layout, cable routing possibility, and available working area from equipment zone.
A14: D.4.2 | B14: Existing Transport Equipment | C14: Check transport equipment, available uplink, rack availability, and possible OLT backhaul integration. Include a photo of the Transport bayface to check available ports, SFPs, and card slots onsite. (Propose location if AN is not ready - power & space specs is provided) | D14: ATN910D Space: 442mm*220mm*44.45mm(1U) Power: 180W (1x10A DC breaker) Weight: 4kg ATN950D Space: 442mm*220mm*88.9mm(2U) Power: 237W (1x10A DC breaker) Power Input: DC/AC,1+1 backup
A15: D.7 | B15: Wireline Cabinet Solution | C15: Use if OLT & TRS equipment will be co-located with an existing outdoor cabinet or cabinet expansion is needed.
A16: D.9 | B16: Basepad Information | C16: Check if there is available basepad or space for new outdoor OLT cabinet, power cabinet, battery cabinet, or compact rack.
A17: I.1 | B17: Existing Site Development Layout | C17: Use as the base layout to identify existing tower, cabinets, genset, fuel tank, AC panel, and access route.
A18: I.2 | B18: Proposed Site Development Layout | C18: Should be updated to show the proposed OLT cabinet/rack location.
A19: I.3 | B19: Existing Room Layout | C19: Draw a simple layout of the rooms and cabinet installed on-site. If outdoor, provide the bayface of the cabinet.
A21: For the sample site, D.4 is very important because it identifies existing cabinet/rack space, including available U-space such as Rack MD4, transport rack, and rectifier rack.
A23: 3. DC Power assessment
A25: Section | B25: Section Title | C25: Use for OLT Assessment
A26: G.1 | B26: Existing DC Power Information | C26: Check existing rectifier system, installed modules, operational modules, spare slots, DC load, float voltage, and DC breaker availability, including Battery Informations
A27: G.2 | B27: Proposed New DC Power Solution | C27: Use if existing rectifier is insufficient and new rectifier, power shelf, or power cabinet is needed.
A28: G.3 | B28: Proposed DC Load Computation | C28: Recompute added OLT load & include transport load, future total load, rectifier sufficiency, breaker size, and battery backup impact.
A30: For OLT projects, G.1 and G.3 should be mandatory. In the sample, G.1 shows the rectifier systems and actual DC load information, while G.3 is used for proposed load and battery backup computation.
A32: 4. AC power Assessment
A34: Section | B34: Section Title | C34: Use for OLT Assessment
A35: H.1 | B35: AC Power Source Information | C35: Confirm if the site has permanent commercial power and identify power provider.
A36: H.2 | B36: Transformer Information | C36: Check transformer capacity and whether it can support added OLT/rectifier load. (Photos only)
A37: H.3 | B37: Other AC Components Information | C37: Review ACPDB, ECB, ATS/MTS, breaker capacity, load schedule, and possible tapping point.
A38: H.4 | B38: Genset and Fuel Tank Information | C38: Confirm backup AC source, genset capacity, fuel tank condition, and readiness to support added OLT load.
A40: In the sample, H.1 to H.4 are part of the approved sections. H.4 also shows genset capacity and fuel tank details, which are needed when assessing backup support for new OLT load.
A42: 5. Cable routing / installation readiness
A44: Section | B44: Section Title | C44: Use for OLT Assessment
A45: D.8 | B45: Cable Ladder for Power and Data Cable | C45: Check existing cable ladder/tray, conduit, route availability, and need for new cable support.
A46: E.2 | B46: Proposed Cable Interface | C46: Reuse this format for OLT power cable, fiber patch cord, grounding cable, uplink cable, and cable length requirements.
A47: I.4 | B47: Proposed Room Layout with Cable Routing Layout | C47: Use if indoor/cabin/rack installation applies.
A48: I.5 | B48: Proposed Outdoor Cable Routing | C48: Use for outdoor cabinet, outdoor OLT, fiber entry, power routing, and grounding route. Show fiber route from OLT cabinet/rack to ODF cabinet/rack to the FDT/OSP/CEF entry point.
A50: For Broadband OLT, E.2 should be modified because the current template is more mobile/RRU-based. It should be adjusted to reflect OLT requirements such as DC power cable, ODF/fiber jumper, transport uplink, grounding, and alarm cable.
A52: 6. Grounding, protection, and safety readiness
A54: Section | B54: Section Title | C54: Use for OLT Assessment
A55: D.11 | B55: Busbar Information | C55: Check available busbar, grounding tapping point, and whether existing busbar can be reused.
A56: D.12 | B56: Grounding Wire Requirement | C56: Use if additional grounding wire is needed for new OLT cabinet/rack.
...

Sheet DAS-Existing
J2: =#REF! -> #REF!
J3: Technical Site Survey Report
J4: Site Name / Search Ring Name : | O4: =#REF! -> #REF!
J5: PLA ID | O5: =#REF! -> #REF! | AP5: ist
C6: B5. DISTRIBUTED RF Antenna Information
C7: B5.1. Existing RF Antenna Information
D9: G900/U900 | N9: Sector 1 | V9: Sector 2 | AD9: Sector 3
D10: Latitude (DLL) of Antenna
D11: Longitude (DLL) of Antenna
D12: Tower type
D13: Tower/Pole Height (m)
D14: Building height (m) | R14: m | Z14: m | AH14: m
D15: Total Height (Bldg.+Tower) (m) | R15: m | Z15: m | AH15: m
D16: Sector 1 | O16: Sector 2 | Z16: Sector 3
D17: Actual GPS Reading | O17: Actual GPS Reading | Z17: Actual GPS Reading
D27: G900/U900 | N27: Sector 4 | V27: Sector 5 | AD27: Sector 6
D28: Latitude (DLL) of Antenna
D29: Longitude (DLL) of Antenna
D30: Tower type
D31: Tower/Pole Height (m)
D32: Building height (m) | R32: m | Z32: m | AH32: m
D33: Total Height (Bldg.+Tower) (m) | R33: m | Z33: m | AH33: m
D34: Sector 4 | O34: Sector 5 | Z34: Sector 6
D35: Actual GPS Reading | O35: Actual GPS Reading | Z35: Actual GPS Reading
D45: L700 | N45: Sector 1 | V45: Sector 2 | AD45: Sector 3
D46: Latitude (DLL) of Antenna
D47: Longitude (DLL) of Antenna
D48: Tower type
D49: Tower/Pole Height (m)
D50: Building height (m) | R50: m | Z50: m | AH50: m
D51: Total Height (Bldg.+Tower) (m) | R51: m | Z51: m | AH51: m
D52: Sector 1 | O52: Sector 2 | Z52: Sector 3
D53: Actual GPS Reading | O53: Actual GPS Reading | Z53: Actual GPS Reading
D63: L700 | N63: Sector 4 | V63: Sector 5 | AD63: Sector 6
D64: Latitude (DLL) of Antenna
D65: Longitude (DLL) of Antenna
D66: Tower type
D67: Tower/Pole Height (m)
D68: Building height (m) | R68: m | Z68: m | AH68: m
D69: Total Height (Bldg.+Tower) (m) | R69: m | Z69: m | AH69: m
...

Sheet TOWER -rf-cw
A1: TOWER TYPE | B1: =Mark1903406000 -> 0
A2: antenna | H2: stand alone RRU | K2: MW
A3: Height | B3: phtsysc Ant. | C3: status | D3: brand | E3: model | F3: share with | G3: RRUB2B | H3: height | I3: RRU used for | J3: model | K3: HEIGHT | L3: SIZE | M3: AZIMUTH | N3: REMARK
A4: 25 | B4: 1
A5: 25 | B5: 2
A6: 25 | B6: 3
A7: xx | B7: 4
A8: xx | B8: 5
A9: xx | B9: 6
A10: xx | B10: 7
A11: xx | B11: 9
A14: WITH DRAWINGS

Sheet B-Sol MIMO-2600
J2: =#REF! -> #REF!
J3: Technical Site Survey Report
J4: Site Name | O4: =#REF! -> #REF!
J5: PLA ID | O5: =#REF! -> #REF!
C6: B1. RF Antenna Information
C7: B1.1. General Information
E8: Enough space to install RF antenna of this project? | AF8: Antenna
D10: Proposal for MIMO (Horizontal MIMO) | N10: Sector 1 | V10: Sector 2 | AD10: Sector 3
D11: Latitude (DLL) of Antenna
D12: Longitude (DLL) of Antenna
D13: Antenna Height (m)
D14: Antenna Orientation
D15: Down tilt (Mechanical)
D16: Down tilt (Electrical)
D17: Type/Model of Antenna
D18: Tech Antenna Shared with
D19: RRU Shared with/Combiner Type
D20: Antenna solution
D21: RRU solution | N21: N/A | V21: N/A | AD21: N/A | AN21: N/A
D22: =N10 -> Sector 1 | O22: =V10 -> Sector 2 | Z22: =AD10 -> Sector 3
D23: Shot of Coverage objectives | O23: Shot of Coverage objectives | Z23: Shot of Coverage objectives
D32: RRU/RFU Location
D40: Overview of Antenna
E56: NEW AMB (specify) | P56: NEW AMB (specify) | AA56: NEW AMB (specify)
E58: REUSE AMB / REFURBISHMENT | P58: REUSE AMB / REFURBISHMENT | AA58: REUSE AMB / REFURBISHMENT
E59: AMB REFURBISHMENT | P59: AMB REFURBISHMENT
D60: New Copper lightning arrester (16mm Ø x 1.5m): | AC60: pcs
C61: C8. Cable Interface | Z61: =D10 -> Proposal for MIMO (Horizontal MIMO)
D62: Power Cable: | AD62: LENGTH
D63: Cable Routing:
E64: Single Length of -48V from EPU to RECTIFIER | AH64: m
E65: Single Length of -48V from RRU/RFU to DCDU | AA65: Sector 1 | AH65: m
AA66: Sector 2 | AH66: m
AA67: Sector 3 | AH67: m
AA68: Sector 4 | AH68: m
AA69: Sector 5 | AH69: m
AA70: Sector 6 | AH70: m
E72: Single Length of -48V from AAU to EPU | AA72: Sector 1 | AH72: m
AA73: Sector 2 | AH73: m
AA74: Sector 3 | AH74: m
...

Sheet B-Sol L23
J2: =#REF! -> #REF!
J3: Technical Site Survey Report
J4: Site Name | O4: =#REF! -> #REF!
J5: PLA ID | O5: =#REF! -> #REF!
C6: B1. RF Antenna Information
C7: B1.1. General Information
E8: Enough space to install RF antenna of this project? | AF8: Antenna
D10: Proposal for L23 | N10: Sector 1 | V10: Sector 2 | AD10: Sector 3
D11: Latitude (DLL) of Antenna
D12: Longitude (DLL) of Antenna
D13: Antenna Height (m)
D14: Antenna Orientation
D15: Down tilt (Mechanical)
D16: Down tilt (Electrical)
D17: Type/Model of Antenna
D18: Tech Antenna Shared with
D19: RRU Shared with/Combiner Type
D20: Antenna solution
D21: RRU solution | AN21: N/A
D22: =N10 -> Sector 1 | O22: =V10 -> Sector 2 | Z22: =AD10 -> Sector 3
D23: Shot of Coverage objectives | O23: Shot of Coverage objectives | Z23: Shot of Coverage objectives
D32: RRU/RFU Location
D40: Overview of Antenna
E56: NEW AMB (specify) | P56: NEW AMB (specify) | AA56: NEW AMB (specify)
E58: REUSE AMB / REFURBISHMENT | P58: REUSE AMB / REFURBISHMENT | AA58: REUSE AMB / REFURBISHMENT
D60: New Copper lightning arrester (16mm Ø x 1.5m): | AC60: pcs
C61: C8. Cable Interface | Z61: =D10 -> Proposal for L23
D62: Power Cable: | AD62: LENGTH
D63: Cable Routing:
E64: Single Length of -48V from EPU to RECTIFIER | AH64: m
E65: Single Length of -48V from RRU/RFU to DCDU | AA65: Sector 1 | AH65: m
AA66: Sector 2 | AH66: m
AA67: Sector 3 | AH67: m
E69: Single Length of -48V from AAU to EPU | AA69: Sector 1 | AH69: m
AA70: Sector 2 | AH70: m
AA71: Sector 3 | AH71: m
D72: PGND Cable:
E73: Single Length of Grounding Cable from L-Rack to Grounding Busbar | AH73: m
E74: Single Length of Grounding Cable from RRU/RFU to Grounding Busbar | AH74: m
E75: Single Length of Grounding Cable from AAU to Grounding Busbar | AH75: m
...

Sheet Pre-Propose pictures
J2: ='[5]FRONT PAGE'!D8 -> <<project(Mark1903361000)>>
J3: Technical Site Survey Report
J4: Site Name | O4: =#REF! -> #REF!
J5: PLA ID | O5: =#REF! -> #REF!
C6: Possible location for upcoming antennas/AAU
D7: Possible location1 for propose Antennas/AAU
D8: sector1 | O8: sector2 | Z8: sector3
D17: Possible location2 for propose Antennas/AAU
D26: Possible location3 for propose Antennas/AAU
C36: Possible location for equipment
E45: possible location1 for cabinet | P45: possible location1 for cabinet | AA45: possible location1 for cabinet
E55: possible location1 for TMC | P55: possible location2 for TMC | AB55: possible location3 for TMC
E66: possible location1 for Basepad | P66: possible location1 for Basepad | AB66: possible location1 for Basepad

Sheet TSSR Proposed Template
B2: Antenna Name | K2: Antenna 2 | S2: Antenna 3 | AA2: Antenna 4 | AB2: Antenna 5 | AC2: Antenna 6 | AD2: Antenna 7
B3: Antenna Brand
B4: Antenna Model
B5: Serial No.
B6: Asset No.
B7: Power Output (Watts)
B8: Cell Coverage | E8: Indoor, Outdoor, OSI
B9: Solution Type | E9: Macro, Easy Macro, Pico, Atom
B10: Dual Beam | E10: Yes Or No
B11: Cell Coverage Objective | D11: Intended coverage area (Barangay, building, exact locations
B12: Ant. Latitude | C12: 14.231231 | K12: 14.231231 | S12: 14.231231 | AA12: 14.231231 | AB12: 14.231231 | AC12: 14.231231 | AD12: 14.231231
B13: Ant. Longitude | C13: 120.14126 | K13: 120.14126 | S13: 120.14126 | AA13: 120.14126 | AB13: 120.14126 | AC13: 120.14126 | AD13: 120.14126
B14: Sector Number | C14: 1 | K14: 2 | L14: 2 | M14: 2 | N14: 2 | O14: 2 | P14: 2 | Q14: 2 | R14: 2 | S14: 3 | T14: 3 | U14: 3 | V14: 3 | W14: 3 | X14: 3 | Y14: 3 | Z14: 3 | AA14: 1 | AB14: 2 | AC14: 3 | AD14: 3
B15: Azimuth | C15: 0 | K15: 90 | S15: 180 | AA15: 0 | AB15: 90 | AC15: 180 | AD15: 180
B16: Tower Height
B17: Building Height
B18: with RET | F18: Yes or No
B19: Feeder Type
B20: Feeder Length (m)
B21: Elevation (ACL, building + tower ht.) | C21: 39 | K21: 39 | S21: 39 | AA21: 36 | AB21: 36 | AC21: 36 | AD21: 36
B22: Mechanical Tilt | C22: 2 | K22: 2 | S22: 2 | AA22: - | AB22: - | AC22: - | AD22: -
B23: No. of Ports
B24: RRU/Combiner Model
B25: Antenna Status | F25: Proposed, For Implementation, In Service, For Decommissioning
B26: Technology | C26: G9 | D26: G18 | E26: U9 | F26: L7 | G26: U21 | H26: L18 | I26: L7 | J26: L26 | K26: L23 | L26: G9 | M26: U9 | N26: L7 | O26: U21 | P26: L18 | Q26: L7 | R26: L26 | S26: L23 | T26: G9 | U26: U9 | V26: L7 | W26: U21 | X26: L18 | Y26: L7 | Z26: L26 | AA26: L23 | AB26: L26 MM | AC26: L26 MM | AD26: L26 MM | AE26: NR35
C27: On-Air, Proposed, For Implementation, For Decommissioning | D27: On-Air, Proposed, For Implementation, For Decommissioning | E27: On-Air, Proposed, For Implementation, For Decommissioning | F27: On-Air, Proposed, For Implementation, For Decommissioning | G27: On-Air, Proposed, For Implementation, For Decommissioning | H27: On-Air, Proposed, For Implementation, For Decommissioning | I27: On-Air, Proposed, For Implementation, For Decommissioning | J27: On-Air, Proposed, For Implementation, For Decommissioning | K27: On-Air, Proposed, For Implementation, For Decommissioning | L27: On-Air, Proposed, For Implementation, For Decommissioning | M27: On-Air, Proposed, For Implementation, For Decommissioning | N27: On-Air, Proposed, For Implementation, For Decommissioning | O27: On-Air, Proposed, For Implementation, For Decommissioning | P27: On-Air, Proposed, For Implementation, For Decommissioning | Q27: On-Air, Proposed, For Implementation, For Decommissioning | R27: On-Air, Proposed, For Implementation, For Decommissioning | S27: On-Air, Proposed, For Implementation, For Decommissioning | T27: On-Air, Proposed, For Implementation, For Decommissioning | U27: On-Air, Proposed, For Implementation, For Decommissioning | V27: On-Air, Proposed, For Implementation, For Decommissioning | W27: On-Air, Proposed, For Implementation, For Decommissioning | X27: On-Air, Proposed, For Implementation, For Decommissioning | Y27: On-Air, Proposed, For Implementation, For Decommissioning | Z27: On-Air, Proposed, For Implementation, For Decommissioning | AA27: On-Air, Proposed, For Implementation, For Decommissioning
B28: Configuration | C28: # of Carriers | D28: # of Carriers | E28: # of Carriers | F28: # of Carriers | G28: # of Carriers | H28: # of Carriers | I28: # of Carriers | J28: # of Carriers | K28: # of Carriers
B29: Electrical Tilt | C29: 2 | D29: 2 | E29: 2 | F29: 2 | G29: 2 | H29: 2 | I29: 2 | J29: 2 | K29: 2 | L29: 2 | M29: 2 | N29: 2 | O29: 2 | P29: 2 | Q29: 2 | R29: 2 | S29: 2 | T29: 2 | U29: 2 | V29: 2 | W29: 2 | X29: 2 | Y29: 2 | Z29: 2 | AA29: 2 | AB29: - | AC29: - | AD29: - | AE29: -
B30: Tower Type | C30: 40-meter SST | AE30: *Captured In Facilities
B31: Cabin (Indoor/Outdoor) | C31: Outdoor | AE31: *Captured In Facilities
B35: RRU Name
B36: RRU Model
B37: Asset No.
B38: Serial No.
B39: RRU Location | C39: Top, Down
B40: RRU Status | F40: Proposed, For Implementation, In Service, For Decommissioning
B41: BBU-RRU FOC Length (m)
B42: Technology | C42: G9 | D42: G18 | E42: U9 | F42: L7 | G42: U21 | H42: L18 | I42: L7 | J42: L26 | K42: L23
C43: On-Air, Proposed, For Implementation, For Decommissioning | D43: On-Air, Proposed, For Implementation, For Decommissioning | E43: On-Air, Proposed, For Implementation, For Decommissioning | F43: On-Air, Proposed, For Implementation, For Decommissioning | G43: On-Air, Proposed, For Implementation, For Decommissioning | H43: On-Air, Proposed, For Implementation, For Decommissioning | I43: On-Air, Proposed, For Implementation, For Decommissioning | J43: On-Air, Proposed, For Implementation, For Decommissioning | K43: On-Air, Proposed, For Implementation, For Decommissioning
B44: Sector Number | C44: 1 | K44: 1
...

Sheet B-Sol MIMO-1800
J2: =#REF! -> #REF!
J3: Technical Site Survey Report
J4: Site Name | O4: =#REF! -> #REF!
J5: PLA ID | O5: =#REF! -> #REF!
C6: B1. RF Antenna Information
C7: B1.1. General Information
E8: Enough space to install RF antenna of this project? | AF8: Antenna
D10: Proposal for MIMO (Horizontal MIMO) | N10: Sector 1 | V10: Sector 2 | AD10: Sector 3
D11: Latitude (DLL) of Antenna
D12: Longitude (DLL) of Antenna
D13: Antenna Height (m)
D14: Antenna Orientation
D15: Down tilt (Mechanical)
D16: Down tilt (Electrical)
D17: Type/Model of Antenna
D18: Tech Antenna Shared with
D19: RRU Shared with/Combiner Type
D20: Antenna solution
D21: RRU solution | N21: N/A | V21: N/A | AD21: N/A
D22: =N10 -> Sector 1 | O22: =V10 -> Sector 2 | Z22: =AD10 -> Sector 3
D23: Shot of Coverage objectives | O23: Shot of Coverage objectives | Z23: Shot of Coverage objectives
D32: RRU/RFU Location
D40: Overview of Antenna
E56: NEW AMB (specify) | P56: NEW AMB (specify) | AA56: NEW AMB (specify)
E58: REUSE AMB / REFURBISHMENT | P58: REUSE AMB / REFURBISHMENT | AA58: REUSE AMB / REFURBISHMENT
E59: AMB REFURBISHMENT | P59: AMB REFURBISHMENT | AA59: AMB REFURBISHMENT
D60: New Copper lightning arrester (16mm Ø x 1.5m): | AC60: pcs
C61: C8. Cable Interface | Z61: =D10 -> Proposal for MIMO (Horizontal MIMO)
D62: Power Cable: | AD62: LENGTH
D63: Cable Routing:
E64: Single Length of -48V from EPU to RECTIFIER | AH64: m
E65: Single Length of -48V from RRU/RFU to DCDU | AA65: Sector 1 | AH65: m
AA66: Sector 2 | AH66: m
AA67: Sector 3 | AH67: m
AA68: Sector 4 | AH68: m
AA69: Sector 5 | AH69: m
AA70: Sector 6 | AH70: m
E72: Single Length of -48V from AAU to EPU | AA72: Sector 1 | AH72: m
AA73: Sector 2 | AH73: m
AA74: Sector 3 | AH74: m
...

Sheet B-Sol U2100DB
J2: =#REF! -> #REF!
J3: Technical Site Survey Report
J4: Site Name | O4: =#REF! -> #REF!
J5: PLA ID | O5: =#REF! -> #REF!
C6: B1. RF Antenna Information
C7: B1.1. General Information
E8: Enough space to install RF antenna of this project? | AF8: Antenna
D10: Proposal for U2100DB | N10: Sector 1 | V10: Sector 2 | AD10: Sector 3
D11: Latitude (DLL) of Antenna
D12: Longitude (DLL) of Antenna
D13: Antenna Height (m)
D14: Antenna Orientation
D15: Down tilt (Mechanical)
D16: Down tilt (Electrical)
D17: Type/Model of Antenna
D18: Tech Antenna Shared with
D19: RRU Shared with/Combiner Type
D20: Antenna solution
D21: RRU solution
D22: =N10 -> Sector 1 | O22: =V10 -> Sector 2 | Z22: =AD10 -> Sector 3
D23: Shot of Coverage objectives | O23: Shot of Coverage objectives | Z23: Shot of Coverage objectives
D33: RRU/RFU Location
D41: Overview of Antenna
E57: NEW AMB (specify) | P57: NEW AMB (specify) | AA57: NEW AMB (specify)
E59: REUSE AMB / REFURBISHMENT | P59: REUSE AMB / REFURBISHMENT | AA59: REUSE AMB / REFURBISHMENT
E60: AMB REFURBISHMENT | P60: AMB REFURBISHMENT | AA60: AMB REFURBISHMENT
D61: New Copper lightning arrester (16mm Ø x 1.5m): | AC61: pcs
D63: Proposal for U2100DB | N63: Sector 4 | V63: Sector 5 | AD63: Sector 6
D64: Latitude (DLL) of Antenna
D65: Longitude (DLL) of Antenna
D66: Antenna Height (m)
D67: Antenna Orientation
D68: Down tilt (Mechanical)
D69: Down tilt (Electrical)
D70: Type/Model of Antenna
D71: Tech Antenna Shared with
D72: RRU Shared with/Combiner Type
D73: Antenna solution
D74: RRU solution
D75: =N63 -> Sector 4 | O75: =V63 -> Sector 5 | Z75: =AD63 -> Sector 6
...

Sheet B-Sol L1800(DB)
J2: =#REF! -> #REF!
J3: Technical Site Survey Report
J4: Site Name | O4: =#REF! -> #REF!
J5: PLA ID | O5: =#REF! -> #REF!
C6: B1. RF Antenna Information
C7: B1.1. General Information
E8: Enough space to install RF antenna of this project? | AF8: Antenna
D10: Proposal for L1800/DB | N10: Sector 1 | V10: Sector 2 | AD10: Sector 3
D11: Latitude (DLL) of Antenna
D12: Longitude (DLL) of Antenna
D13: Antenna Height (m)
D14: Antenna Orientation
D15: Down tilt (Mechanical)
D16: Down tilt (Electrical)
D17: Type/Model of Antenna
D18: Antenna vertical separation | R18: =IF(N18=AJ18,"","m") | Z18: =IF(V18=AR18,"","m") | AH18: =IF(AD18=AZ18,"","m")
D19: Antenna horizontal separation | R19: =IF(N19=AJ19,"","m") | Z19: =IF(V19=AR19,"","m") | AH19: =IF(AD19=AZ19,"","m")
D20: Tech Antenna Shared with
D21: Used of SBT (Yes/No)
D22: RRU/Combiner Model
D23: RRU/Combiner Type
D24: RRU Shared with/Combiner Type
D25: Antenna solution
D26: RRU solution
D27: =N10 -> Sector 1 | O27: =V10 -> Sector 2 | Z27: =AD10 -> Sector 3
D28: Shot of Coverage objectives | O28: Shot of Coverage objectives | Z28: Shot of Coverage objectives
D38: RRU/RFU Location
D46: Overview of Antenna
E62: NEW AMB (specify) | P62: NEW AMB (specify) | AA62: NEW AMB (specify)
E64: REUSE AMB / REFURBISHMENT | P64: REUSE AMB / REFURBISHMENT | AA64: REUSE AMB / REFURBISHMENT
E65: AMB REFURBISHMENT | P65: AMB REFURBISHMENT | AA65: AMB REFURBISHMENT
D66: New Copper lightning arrester (16mm Ø x 1.5m): | AC66: pcs
D68: =D10 -> Proposal for L1800/DB | N68: Sector 4 | V68: Sector 5 | AD68: Sector 6
D69: Latitude (DLL) of Antenna
D70: Longitude (DLL) of Antenna
D71: Antenna Height (m)
D72: Antenna Orientation
D73: Down tilt (Mechanical)
D74: Down tilt (Electrical)
D75: Type/Model of Antenna
...

Sheet B-Sol L700
J2: =#REF! -> #REF!
J3: Technical Site Survey Report
J4: Site Name | O4: =#REF! -> #REF!
J5: PLA ID | O5: =#REF! -> #REF!
C6: B1. RF Antenna Information
C7: B1.1. General Information
E8: Enough space to install RF antenna of this project? | AF8: Antenna
D10: Proposal for L700 | N10: Sector 1 | V10: Sector 2 | AD10: Sector 3
D11: Latitude (DLL) of Antenna
D12: Longitude (DLL) of Antenna
D13: Antenna Height (m)
D14: Antenna Orientation
D15: Down tilt (Mechanical)
D16: Down tilt (Electrical)
D17: Type/Model of Antenna
D18: Tech Antenna Shared with
D19: RRU Shared with/Combiner Type
D20: Antenna solution
D21: RRU solution
D22: =N10 -> Sector 1 | O22: =V10 -> Sector 2 | Z22: =AD10 -> Sector 3
D23: Shot of Coverage objectives | O23: Shot of Coverage objectives | Z23: Shot of Coverage objectives
D33: RRU/RFU Location
D41: Overview of Antenna
E57: NEW AMB (specify) | P57: NEW AMB (specify) | AA57: NEW AMB (specify)
E59: REUSE AMB / REFURBISHMENT | P59: REUSE AMB / REFURBISHMENT | AA59: REUSE AMB / REFURBISHMENT
E60: AMB REFURBISHMENT | P60: AMB REFURBISHMENT | AA60: AMB REFURBISHMENT
D61: New Copper lightning arrester (16mm Ø x 1.5m): | AC61: pcs
D63: =D10 -> Proposal for L700 | N63: Sector 4 | V63: Sector 5 | AD63: Sector 6
D64: Latitude (DLL) of Antenna
D65: Longitude (DLL) of Antenna
D66: Antenna Height (m)
D67: Antenna Orientation
D68: Down tilt (Mechanical)
D69: Down tilt (Electrical)
D70: Type/Model of Antenna
D71: Antenna vertical separation | R71: =IF(N71=AJ71,"","m") | Z71: =IF(V71=AR71,"","m") | AH71: =IF(AD71=AZ71,"","m")
D72: Antenna horizontal separation | R72: =IF(N72=AJ72,"","m") | Z72: =IF(V72=AR72,"","m") | AH72: =IF(AD72=AZ72,"","m")
D73: Tech Antenna Shared with
D74: Used of SBT (Yes/No)
D75: RRU/Combiner Model
...

Sheet B-Sol L2600
J2: =#REF! -> #REF!
J3: Technical Site Survey Report
J4: Site Name | O4: =#REF! -> #REF!
J5: PLA ID | O5: =#REF! -> #REF!
C6: B1. RF Antenna Information
C7: B1.1. General Information
E8: Enough space to install RF antenna of this project? | AF8: Antenna
D10: Proposal for L2600 | N10: Sector 1 | V10: Sector 2 | AD10: Sector 3
D11: Latitude (DLL) of Antenna
D12: Longitude (DLL) of Antenna
D13: Antenna Height (m)
D14: Antenna Orientation
D15: Down tilt (Mechanical)
D16: Down tilt (Electrical)
D17: Type/Model of Antenna
D18: Tech Antenna Shared with
D19: RRU Shared with/Combiner Type
D20: Antenna solution
D21: RRU solution
D22: =N10 -> Sector 1 | O22: =V10 -> Sector 2 | Z22: =AD10 -> Sector 3
D23: Shot of Coverage objectives | O23: Shot of Coverage objectives | Z23: Shot of Coverage objectives
D33: RRU/RFU Location
D41: Overview of Antenna
E57: NEW AMB (specify) | P57: NEW AMB (specify) | AA57: NEW AMB (specify)
E59: REUSE AMB / REFURBISHMENT | P59: REUSE AMB / REFURBISHMENT | AA59: REUSE AMB / REFURBISHMENT
E60: AMB REFURBISHMENT | P60: AMB REFURBISHMENT | AA60: AMB REFURBISHMENT
D61: New Copper lightning arrester (16mm Ø x 1.5m): | AC61: pcs
D63: =D10 -> Proposal for L2600 | N63: Sector 4 | V63: Sector 5 | AD63: Sector 6
D64: Latitude (DLL) of Antenna
D65: Longitude (DLL) of Antenna
D66: Antenna Height (m)
D67: Antenna Orientation
D68: Down tilt (Mechanical)
D69: Down tilt (Electrical)
D70: Type/Model of Antenna
D71: Tech Antenna Shared with
D72: RRU Shared with/Combiner Type
D73: Antenna solution
D74: RRU solution
D75: =N63 -> Sector 4 | O75: =V63 -> Sector 5 | Z75: =AD63 -> Sector 6
...

Sheet DAS-Proposed
J2: =#REF! -> #REF!
J3: Technical Site Survey Report
J4: Site Name / Search Ring Name : | O4: =#REF! -> #REF!
J5: PLA ID | O5: =#REF! -> #REF! | AP5: ist
C6: B5. DISTRIBUTED RF Antenna Information
C7: B5.1. Proposed RF Antenna Information
D9: Proposal for ------ | N9: Sector 1 | V9: Sector 2 | AD9: Sector 3
D10: Latitude (DLL) of Antenna
D11: Longitude (DLL) of Antenna
D12: ACL Antenna Height (m)
D13: Antenna Orientation
D14: Down tilt (Mechanical)
D15: Down tilt (Electrical)
D16: Type/Model of Antenna
D17: Shared Antenna with any technology
D18: RET in Deg/Combiner Connector | N18: N/A | V18: N/A | AD18: N/A
D19: RRU/Combiner Model
D20: RRU Shared with/Combiner Type
D21: AMB TYPE
D22: Tower type
D23: Tower/Pole Height (m)
D24: Building height (m) | R24: m | Z24: m | AH24: m
D25: Total Height (Bldg.+Tower) (m) | R25: =IF(N25=AJ25,"","m") | Z25: =IF(V25=AR25,"","m") | AH25: =IF(AD25=AZ25,"","m")
D26: Sector 1 | O26: Sector 2 | Z26: Sector 3
D27: Target Coverage Objectives | O27: Target Coverage Objectives | Z27: Target Coverage Objectives
D36: RRU/RFU Location
D44: Overview of Antenna
E60: NEW AMB (specify) | P60: NEW AMB (specify) | AA60: NEW AMB (specify)
E62: REUSE AMB / REFURBISHMENT | P62: REUSE AMB / REFURBISHMENT | AA62: REUSE AMB / REFURBISHMENT
D63: New Copper lightning arrester (16mm Ø x 1.5m): | AC63: pcs
C64: B5.1.1. Cable Interface
D65: Power Cable: | AD65: LENGTH
E66: Single Length of -48V from DCDU to RECTIFIER | AH66: m
E67: Single Length of -48V from RRU/RFU to DCDU | AA67: Sector 1 | AH67: m
AA68: Sector 2 | AH68: m
AA69: Sector 3 | AH69: m
D70: PGND Cable:
E71: Single Length of Grounding Cable from L-Rack to Grounding Busbar | AH71: m
E72: Single Length of Grounding Cable from RRU/RFU to Grounding Busbar | AH72: m
E73: Single Length of Grounding Cable from New Tower Busbar to Test Pit | AH73: m
...

Sheet X
B1: H.1 | I1: AC Power Source (Supply) Information
B3: Primary Power Source
B4: Power Provider
B5: Permanent or Temporary | P5: If Submetered Capacity (AT)
B6: H.2 | I6: Transformer Information
B8: Sharing | S8: If Yes, Indicative Capacity (Kva)
B9: Brand | O9: Capacity (kVA) | AB9: Type
B10: Wire Information | I10: Secondary Wire | R10: Distribution Wire | AF10: Drop Wire
B12: Wire Size (mm2) | I12: N/A | R12: N/A | AF12: N/A
B13: Length (m) | I13: N/A | R13: N/A | AF13: N/A
B14: Cable Type | I14: N/A | R14: N/A | AF14: N/A
B16: H.3 | I16: Other AC Components Information (ATS, MTS, MDP, ECB, ACPBDB)
B18: AC Details | G18: Class/Capacity | L18: Cable Size (mm2) | P18: Cable length (m) | W18: Status | AB18: Line Reading (Vac) | AE18: Line Reading 1 (Aac) | AI18: Line Reading 2 (Aac) | AL18: Line Reading 3 (Aac)
B20: KWHR Meter
B21: ACPDB
B22: ATS
B23: ECB
C24: SITE NAME:
B25: AC Photos and Details
B26: Picture of Transformer/Submetered Load | N26: Zoom in Picture for Capacity | AC26: Drop Wire
B45: ECB Line Reading | N45: ATS Reading | AC45: MTS Reading
B65: MDP | N65: MDP Breakers | AC65: MDP Output Voltage
B89: Line 1 Ampere | N89: Line 2 Ampere | AC89: Line 3 Ampere
B114: ACPDB Photos and Details
B115: ACPBD | N115: Photos | AC115: Remarks
B141: ACPDB Load Schedule
B142: No. | E142: Brand | G142: Rating | I142: No of Pole | N142: Load Description | S142: L1(A) | X142: L2(A) | AB142: Status | AH142: Remarks
B143: 1
B144: 2
B145: 3
B146: 4
B147: 5
B148: 6
B149: 7
B150: 8
B152: Single Line Diagram (SLD)
B153: SLD File | N153: Recommendation and Comment
B158: H.4 | I158: Genset and Fuel Tank Information
B160: No. | G160: Genset Capacity | M160: Condition | Q160: Type | X160: Exyernal Tank Fuel Capacity | AH160: Brand
B163: Picture of Existing Genset
...

Sheet RS1-computation
H2: FFTH HORIZONTAL
H3: Technical Site Survey Report
H4: Site Name | M4: {{SITE_NAME}}
H5: PLA ID | M5: {{SITE_ID}}
B6: C7. Rectifer1 Computation
B7: C7.1. EXISTING RECTIFIER
C8: 1) EXISTING RECTIFIER SYSTEM BRAND - MODEL | Y8: {{rectifier_brand}}
C9: 2) MAXIMUM RECTIFIER MODULES / INSTALLED | Y9: 8 | AE9: {{max_modules}}
C10: 3) RECTIFIER MODULE RATING, WATTS / AMPS | Y10: {{module_rating_w}} | AE10: {{module_rating_a}}
C11: 4) BATTERY BRAND / VOLTAGE RATING | Y11: {{battery_brand}} | AE11: {{battery_voltage}}
C12: 5) NUMBER OF BATTERIES in BANKS / CAPACITY per CELL (AH) | Y12: {{battery_banks}} | AE12: {{battery_capacity_ah}}
C13: 6) PRESENT LOAD READING, PANEL DISPLAY / CLAMP METER (A) | Y13: {{present_load_a}} | AE13: Ampere
C14: 7) RECTIFIER MODULES IN OPERATION | Y14: {{modules_in_operation}} | AE14: modules
C15: 8) ACTUAL FLOAT VOLTAGE (V) | Y15: {{actual_float_voltage_v}} | AE15: Voltage
B17: C7.2. PROPOSED PDU/DCDU RECTIFIER LOAD SCHEDULE
D18: PROPOSED ADDITIONAL LOAD(S)
D19: Load No | G19: Equipment Type (Load Description) | O19: Power Rating (Watts) | S19: Current Rating (Amps) | W19: Cable Size (AWG) | Z19: Circuit Breaker Rating (Amps) | AE19: Deployment Remarks
C21: BAPE | D21: 1 | G21: NOKIA MF-2 | O21: 400 | S21: 7.4 | Z21: 16 | AL21: Power rating Autofill
D22: 2
D23: 3
D24: 4 | AL24: FRPA | AM24: 934
D25: 5 | AL25: FHEL | AM25: 1353
D26: TOTAL: | S26: =(SUM(S21:V25)) -> 7.4 | AL26: AZNA | AM26: 1272
AL27: AZHA | AM27: 1338
D28: Total Full Load Current = | L28: Existing Load + Proposed Load (100% of Rated Load) = | Z28: =Y13+S26 -> #VALUE! | AD28: Amps | AL28: MIMO26N | AM28: 1300
G29: Existing Rectifier Capacity: | P29: No. Modules x Ampere Capacity | Y29: = | Z29: =Y14*AE10 -> #VALUE! | AD29: Amps
G30: Existing Battery Capacity: | P30: No. of Batt Banks x Batt Capacity | Y30: = | Z30: =Y12*AE12 -> #VALUE! | AD30: AH
C32: RECTIFIER SUFFICIENCY COMPUTATION:
C34: Available Rectifier Capacity = | L34: Existing Rectifier Capacity - (Total Full Load Current) - (10% of Battery Capacity)
L35: - Rectifier Module Current Rating
C36: Available Rectifier Capacity = | L36: =Z29 -> #VALUE! | O36: Amps - | R36: =Z28 -> #VALUE! | U36: Amps - | X36: ( | Y36: =Z30 -> #VALUE! | AA36: * | AB36: 0.05) | AD36: - | AE36: =AE10 -> {{module_rating_a}} | AH36: Amps | AL36: 179.78 Amps - 67.99 Amps - (400*0.1) - 44.94 Amps
C37: Available Rectifier Capacity = | L37: =Z29-Z28-(Z30*0.05)-AE10 -> #VALUE! | Q37: Amperes | T37: (if result value is negative, provision of additional module is required)
C38: Percent Utilization (TLC/Existing Rectifier Capacity) | R38: = | S38: =Z28/Z29 -> #VALUE! | AL38: If % utilization is >59% add module
C40: BATTERY BACK-UP TIME COMPUTATION:
C42: BBUT = | F42: BATTERY CAPACITY (AMPERE-HOUR) / FUTURE TOTAL LOAD (AMPERE)
C43: BBUT = | F43: =Z30/Z28 -> #VALUE! | I43: Hours
B45: C7.3. END-STATE SUFFICIENCY COMPUTATION: | R45: (applicable only if there will be new Rectifier System or Upgraded Module)
C47: Available Rectifier Capacity = | L47: (Future Rectifier Capacity - (Total Full Load Current) - (10% of Battery Capacity)
L48: - Rectifier Module Current Rating | AK48: 37.45 | AL48: 7 | AM48: =AK48*AL48 -> 262.15
C49: Available Rectifier Capacity =
...

Sheet RS2-computation
H2: FFTH HORIZONTAL
H3: Technical Site Survey Report
H4: Site Name | M4: {{SITE_NAME}}
H5: PLA ID | M5: {{SITE_ID}}
B6: C7. Rectifer1 Computation
B7: C7.1. EXISTING RECTIFIER
C8: 1) EXISTING RECTIFIER SYSTEM BRAND - MODEL | Y8: {{rectifier_brand}} | AK8: {{rectifier_brand}}
C9: 2) MAXIMUM RECTIFIER MODULES / INSTALLED | Y9: 8 | AE9: {{max_modules}} | AK9: 8 | AQ9: {{max_modules}}
C10: 3) RECTIFIER MODULE RATING, WATTS / AMPS | Y10: {{module_rating_w}} | AE10: {{module_rating_a}} | AK10: {{module_rating_w}} | AQ10: {{module_rating_a}}
C11: 4) BATTERY BRAND / VOLTAGE RATING | Y11: {{battery_brand}} | AE11: {{battery_voltage}} | AK11: {{battery_brand}} | AQ11: {{battery_voltage}}
C12: 5) NUMBER OF BATTERIES in BANKS / CAPACITY per CELL (AH) | Y12: {{battery_banks}} | AE12: {{battery_capacity_ah}} | AK12: {{battery_banks}} | AQ12: {{battery_capacity_ah}}
C13: 6) PRESENT LOAD READING, PANEL DISPLAY / CLAMP METER (A) | Y13: {{present_load_a}} | AE13: Ampere | AK13: {{present_load_a}} | AQ13: Ampere
C14: 7) RECTIFIER MODULES IN OPERATION | Y14: {{modules_in_operation}} | AE14: modules | AK14: {{modules_in_operation}} | AQ14: modules
C15: 8) ACTUAL FLOAT VOLTAGE (V) | Y15: {{actual_float_voltage_v}} | AE15: Voltage | AK15: {{actual_float_voltage_v}} | AQ15: Voltage
B17: C7.2. PROPOSED PDU/DCDU RECTIFIER LOAD SCHEDULE
D18: PROPOSED ADDITIONAL LOAD(S)
D19: Load No | G19: Equipment Type (Load Description) | O19: Power Rating (Watts) | S19: Current Rating (Amps) | W19: Cable Size (AWG) | Z19: Circuit Breaker Rating (Amps) | AE19: Deployment Remarks
C21: BAPE | D21: 1 | G21: NOKIA MF-2 | O21: 400 | S21: 7.4 | Z21: 16 | AL21: Power rating Autofill
D22: 2
D23: 3
D24: 4 | AL24: FRPA | AM24: 934
D25: 5 | AL25: FHEL | AM25: 1353
D26: TOTAL: | S26: =(SUM(S21:V25)) -> 7.4 | AL26: AZNA | AM26: 1272
AL27: AZHA | AM27: 1338
D28: Total Full Load Current = | L28: Existing Load + Proposed Load (100% of Rated Load) = | Z28: =Y13+S26 -> #VALUE! | AD28: Amps | AL28: MIMO26N | AM28: 1300
G29: Existing Rectifier Capacity: | P29: No. Modules x Ampere Capacity | Y29: = | Z29: =Y14*AE10 -> #VALUE! | AD29: Amps
G30: Existing Battery Capacity: | P30: No. of Batt Banks x Batt Capacity | Y30: = | Z30: =Y12*AE12 -> #VALUE! | AD30: AH
C32: RECTIFIER SUFFICIENCY COMPUTATION:
C34: Available Rectifier Capacity = | L34: Existing Rectifier Capacity - (Total Full Load Current) - (10% of Battery Capacity)
L35: - Rectifier Module Current Rating
C36: Available Rectifier Capacity = | L36: =Z29 -> #VALUE! | O36: Amps - | R36: =Z28 -> #VALUE! | U36: Amps - | X36: ( | Y36: =Z30 -> #VALUE! | AA36: * | AB36: 0.05) | AD36: - | AE36: =AE10 -> {{module_rating_a}} | AH36: Amps | AL36: 179.78 Amps - 67.99 Amps - (400*0.1) - 44.94 Amps
C37: Available Rectifier Capacity = | L37: =Z29-Z28-(Z30*0.05)-AE10 -> #VALUE! | Q37: Amperes | T37: (if result value is negative, provision of additional module is required)
C38: Percent Utilization (TLC/Existing Rectifier Capacity) | R38: = | S38: =Z28/Z29 -> #VALUE! | AL38: If % utilization is >59% add module
C40: BATTERY BACK-UP TIME COMPUTATION:
C42: BBUT = | F42: BATTERY CAPACITY (AMPERE-HOUR) / FUTURE TOTAL LOAD (AMPERE)
C43: BBUT = | F43: =Z30/Z28 -> #VALUE! | I43: Hours
B45: C7.3. END-STATE SUFFICIENCY COMPUTATION: | R45: (applicable only if there will be new Rectifier System or Upgraded Module)
C47: Available Rectifier Capacity = | L47: (Future Rectifier Capacity - (Total Full Load Current) - (10% of Battery Capacity)
L48: - Rectifier Module Current Rating | AK48: 37.45 | AL48: 7 | AM48: =AK48*AL48 -> 262.15
C49: Available Rectifier Capacity =
...

Sheet RS3-computation
H2: FFTH HORIZONTAL
H3: Technical Site Survey Report
H4: Site Name | M4: {{SITE_NAME}}
H5: PLA ID | M5: {{SITE_ID}}
B6: C7. Rectifer1 Computation
B7: C7.1. EXISTING RECTIFIER
C8: 1) EXISTING RECTIFIER SYSTEM BRAND - MODEL | Y8: {{rectifier_brand}}
C9: 2) MAXIMUM RECTIFIER MODULES / INSTALLED | Y9: 8 | AE9: {{max_modules}}
C10: 3) RECTIFIER MODULE RATING, WATTS / AMPS | Y10: {{module_rating_w}} | AE10: {{module_rating_a}}
C11: 4) BATTERY BRAND / VOLTAGE RATING | Y11: {{battery_brand}} | AE11: {{battery_voltage}}
C12: 5) NUMBER OF BATTERIES in BANKS / CAPACITY per CELL (AH) | Y12: {{battery_banks}} | AE12: {{battery_capacity_ah}}
C13: 6) PRESENT LOAD READING, PANEL DISPLAY / CLAMP METER (A) | Y13: {{present_load_a}} | AE13: Ampere
C14: 7) RECTIFIER MODULES IN OPERATION | Y14: {{modules_in_operation}} | AE14: modules
C15: 8) ACTUAL FLOAT VOLTAGE (V) | Y15: {{actual_float_voltage_v}} | AE15: Voltage
B17: C7.2. PROPOSED PDU/DCDU RECTIFIER LOAD SCHEDULE
D18: PROPOSED ADDITIONAL LOAD(S)
D19: Load No | G19: Equipment Type (Load Description) | O19: Power Rating (Watts) | S19: Current Rating (Amps) | W19: Cable Size (AWG) | Z19: Circuit Breaker Rating (Amps) | AE19: Deployment Remarks
C21: BAPE | D21: 1 | G21: NOKIA MF-2 | O21: 400 | S21: 7.4 | Z21: 16 | AL21: Power rating Autofill
D22: 2
D23: 3
D24: 4 | AL24: FRPA | AM24: 934
D25: 5 | AL25: FHEL | AM25: 1353
D26: TOTAL: | S26: =(SUM(S21:V25)) -> 7.4 | AL26: AZNA | AM26: 1272
AL27: AZHA | AM27: 1338
D28: Total Full Load Current = | L28: Existing Load + Proposed Load (100% of Rated Load) = | Z28: =Y13+S26 -> #VALUE! | AD28: Amps | AL28: MIMO26N | AM28: 1300
G29: Existing Rectifier Capacity: | P29: No. Modules x Ampere Capacity | Y29: = | Z29: =Y14*AE10 -> #VALUE! | AD29: Amps
G30: Existing Battery Capacity: | P30: No. of Batt Banks x Batt Capacity | Y30: = | Z30: =Y12*AE12 -> #VALUE! | AD30: AH
C32: RECTIFIER SUFFICIENCY COMPUTATION:
C34: Available Rectifier Capacity = | L34: Existing Rectifier Capacity - (Total Full Load Current) - (10% of Battery Capacity)
L35: - Rectifier Module Current Rating
C36: Available Rectifier Capacity = | L36: =Z29 -> #VALUE! | O36: Amps - | R36: =Z28 -> #VALUE! | U36: Amps - | X36: ( | Y36: =Z30 -> #VALUE! | AA36: * | AB36: 0.05) | AD36: - | AE36: =AE10 -> {{module_rating_a}} | AH36: Amps | AL36: 179.78 Amps - 67.99 Amps - (400*0.1) - 44.94 Amps
C37: Available Rectifier Capacity = | L37: =Z29-Z28-(Z30*0.05)-AE10 -> #VALUE! | Q37: Amperes | T37: (if result value is negative, provision of additional module is required)
C38: Percent Utilization (TLC/Existing Rectifier Capacity) | R38: = | S38: =Z28/Z29 -> #VALUE! | AL38: If % utilization is >59% add module
C40: BATTERY BACK-UP TIME COMPUTATION:
C42: BBUT = | F42: BATTERY CAPACITY (AMPERE-HOUR) / FUTURE TOTAL LOAD (AMPERE)
C43: BBUT = | F43: =Z30/Z28 -> #VALUE! | I43: Hours
B45: C7.3. END-STATE SUFFICIENCY COMPUTATION: | R45: (applicable only if there will be new Rectifier System or Upgraded Module)
C47: Available Rectifier Capacity = | L47: (Future Rectifier Capacity - (Total Full Load Current) - (10% of Battery Capacity)
L48: - Rectifier Module Current Rating | AK48: 37.45 | AL48: 7 | AM48: =AK48*AL48 -> 262.15
C49: Available Rectifier Capacity =
...

Sheet RS4-computation
H2: FFTH HORIZONTAL
H3: Technical Site Survey Report
H4: Site Name | M4: {{SITE_NAME}}
H5: PLA ID | M5: {{SITE_ID}}
B6: C7. Rectifer1 Computation
B7: C7.1. EXISTING RECTIFIER
C8: 1) EXISTING RECTIFIER SYSTEM BRAND - MODEL | Y8: {{rectifier_brand}}
C9: 2) MAXIMUM RECTIFIER MODULES / INSTALLED | Y9: 8 | AE9: {{max_modules}}
C10: 3) RECTIFIER MODULE RATING, WATTS / AMPS | Y10: {{module_rating_w}} | AE10: {{module_rating_a}}
C11: 4) BATTERY BRAND / VOLTAGE RATING | Y11: {{battery_brand}} | AE11: {{battery_voltage}}
C12: 5) NUMBER OF BATTERIES in BANKS / CAPACITY per CELL (AH) | Y12: {{battery_banks}} | AE12: {{battery_capacity_ah}}
C13: 6) PRESENT LOAD READING, PANEL DISPLAY / CLAMP METER (A) | Y13: {{present_load_a}} | AE13: Ampere
C14: 7) RECTIFIER MODULES IN OPERATION | Y14: {{modules_in_operation}} | AE14: modules
C15: 8) ACTUAL FLOAT VOLTAGE (V) | Y15: {{actual_float_voltage_v}} | AE15: Voltage
B17: C7.2. PROPOSED PDU/DCDU RECTIFIER LOAD SCHEDULE
D18: PROPOSED ADDITIONAL LOAD(S)
D19: Load No | G19: Equipment Type (Load Description) | O19: Power Rating (Watts) | S19: Current Rating (Amps) | W19: Cable Size (AWG) | Z19: Circuit Breaker Rating (Amps) | AE19: Deployment Remarks
C21: BAPE | D21: 1 | G21: NOKIA MF-2 | O21: 400 | S21: 7.4 | Z21: 16 | AL21: Power rating Autofill
D22: 2
D23: 3
D24: 4 | AL24: FRPA | AM24: 934
D25: 5 | AL25: FHEL | AM25: 1353
D26: TOTAL: | S26: =(SUM(S21:V25)) -> 7.4 | AL26: AZNA | AM26: 1272
AL27: AZHA | AM27: 1338
D28: Total Full Load Current = | L28: Existing Load + Proposed Load (100% of Rated Load) = | Z28: =Y13+S26 -> #VALUE! | AD28: Amps | AL28: MIMO26N | AM28: 1300
G29: Existing Rectifier Capacity: | P29: No. Modules x Ampere Capacity | Y29: = | Z29: =Y14*AE10 -> #VALUE! | AD29: Amps
G30: Existing Battery Capacity: | P30: No. of Batt Banks x Batt Capacity | Y30: = | Z30: =Y12*AE12 -> #VALUE! | AD30: AH
C32: RECTIFIER SUFFICIENCY COMPUTATION:
C34: Available Rectifier Capacity = | L34: Existing Rectifier Capacity - (Total Full Load Current) - (10% of Battery Capacity)
L35: - Rectifier Module Current Rating
C36: Available Rectifier Capacity = | L36: =Z29 -> #VALUE! | O36: Amps - | R36: =Z28 -> #VALUE! | U36: Amps - | X36: ( | Y36: =Z30 -> #VALUE! | AA36: * | AB36: 0.05) | AD36: - | AE36: =AE10 -> {{module_rating_a}} | AH36: Amps | AL36: 179.78 Amps - 67.99 Amps - (400*0.1) - 44.94 Amps
C37: Available Rectifier Capacity = | L37: =Z29-Z28-(Z30*0.05)-AE10 -> #VALUE! | Q37: Amperes | T37: (if result value is negative, provision of additional module is required)
C38: Percent Utilization (TLC/Existing Rectifier Capacity) | R38: = | S38: =Z28/Z29 -> #VALUE! | AL38: If % utilization is >59% add module
C40: BATTERY BACK-UP TIME COMPUTATION:
C42: BBUT = | F42: BATTERY CAPACITY (AMPERE-HOUR) / FUTURE TOTAL LOAD (AMPERE)
C43: BBUT = | F43: =Z30/Z28 -> #VALUE! | I43: Hours
B45: C7.3. END-STATE SUFFICIENCY COMPUTATION: | R45: (applicable only if there will be new Rectifier System or Upgraded Module)
C47: Available Rectifier Capacity = | L47: (Future Rectifier Capacity - (Total Full Load Current) - (10% of Battery Capacity)
L48: - Rectifier Module Current Rating | AK48: 37.45 | AL48: 7 | AM48: =AK48*AL48 -> 262.15
C49: Available Rectifier Capacity =
...

Sheet RS3-computation (existing)
H2: ='RS2-computation (existing)'!H2:AD2 -> #REF!
H3: Technical Site Survey Report
H4: Site Name | M4: ='RS2-computation (existing)'!M4:AD4 -> #REF!
H5: PLA ID | M5: ='RS2-computation (existing)'!M5:AD5 -> #REF!
B6: C7. Rectifer3 Computation
B7: C7.1. EXISTING RECTIFIER
C8: 1) EXISTING RECTIFIER SYSTEM BRAND - MODEL | Y8: =#REF! -> #REF!
C9: 2) MAXIMUM RECTIFIER MODULES / INSTALLED | Y9: =#REF!+#REF! -> #REF! | AE9: =#REF! -> #REF!
C10: 3) RECTIFIER MODULE RATING, WATTS / AMPS | Y10: =#REF! -> #REF! | AE10: =#REF! -> #REF!
C11: 4) BATTERY BRAND / VOLTAGE RATING | Y11: =#REF! -> #REF! | AE11: =#REF! -> #REF!
C12: 5) NUMBER OF BATTERIES in BANKS / CAPACITY per CELL (AH) | Y12: =#REF! -> #REF! | AE12: =#REF! -> #REF!
C13: 6) PRESENT LOAD READING, PANEL DISPLAY / CLAMP METER (A) | Y13: =#REF! -> #REF! | AE13: Ampere
C14: 7) RECTIFIER MODULES IN OPERATION | Y14: 4 | AE14: modules
C15: 8) ACTUAL FLOAT VOLTAGE (V) | Y15: =#REF! -> #REF! | AE15: Voltage
B17: C7.2. PROPOSED PDU/DCDU RECTIFIER LOAD SCHEDULE
D18: PROPOSED ADDITIONAL LOAD(S)
D19: Load No | G19: Equipment Type (Load Description) | O19: Power Rating (Watts) | S19: Current Rating (Amps) | W19: Cable Size (AWG) | Z19: Circuit Breaker Rating (Amps) | AE19: Deployment Remarks
D21: 1 | AL21: Power rating Autofill
D22: 2
D23: 3
D24: 4
D25: 5
D26: 6
D27: 7
D28: TOTAL: | S28: =(SUM(S21:V27)) -> 0
D30: Total Full Load Current = | L30: Existing Load + Proposed Load (100% of Rated Load) = | Z30: =Y13+S28 -> #REF! | AD30: Amps
G31: Existing Rectifier Capacity: | P31: No. Modules x Ampere Capacity | Y31: = | Z31: =Y14*AE10 -> #REF! | AD31: Amps
G32: Existing Battery Capacity: | P32: No. of Batt Banks x Batt Capacity | Y32: = | Z32: =Y12*AE12 -> #REF! | AD32: AH
C34: RECTIFIER SUFFICIENCY COMPUTATION:
C36: Available Rectifier Capacity = | L36: Existing Rectifier Capacity - (Total Full Load Current) - (10% of Battery Capacity)
L37: - Rectifier Module Current Rating
C38: Available Rectifier Capacity = | L38: =Z31 -> #REF! | O38: Amps - | R38: =Z30 -> #REF! | U38: Amps - | X38: ( | Y38: =Z32 -> #REF! | AA38: * | AB38: 0.05) | AD38: - | AE38: =AE10 -> #REF! | AH38: Amps | AL38: 179.78 Amps - 67.99 Amps - (400*0.1) - 44.94 Amps
C39: Available Rectifier Capacity = | L39: =Z31-Z30-(Z32*0.05)-AE10 -> #REF! | Q39: Amperes | T39: (if result value is negative, provision of additional module is required)
C40: Percent Utilization (TLC/Existing Rectifier Capacity) | R40: = | S40: =Z30/Z31 -> #REF! | AL40: If % utilization is >59% add module
C42: BATTERY BACK-UP TIME COMPUTATION:
C44: BBUT = | F44: BATTERY CAPACITY (AMPERE-HOUR) / FUTURE TOTAL LOAD (AMPERE)
C45: BBUT = | F45: =Z32/Z30 -> #REF! | I45: Hours
B47: C7.3. END-STATE SUFFICIENCY COMPUTATION: | R47: (applicable only if there will be new Rectifier System or Upgraded Module)
C49: Available Rectifier Capacity = | L49: (Future Rectifier Capacity - (Total Full Load Current) - (10% of Battery Capacity)
L50: - Rectifier Module Current Rating | AK50: 37.45 | AL50: 7 | AM50: =AK50*AL50 -> 262.15
...

Sheet RS4-computation (existing)
H2: ='RS3-computation (existing)'!H2:AD2 -> #REF!
H3: Technical Site Survey Report
H4: Site Name | M4: ='RS3-computation (existing)'!M4:AD4 -> #REF!
H5: PLA ID | M5: ='RS3-computation (existing)'!M5:AD5 -> #REF!
B6: C7. Rectifer4 Computation
B7: C7.1. EXISTING RECTIFIER 4
C8: 1) EXISTING RECTIFIER SYSTEM BRAND - MODEL | Y8: =#REF! -> #REF!
C9: 2) MAXIMUM RECTIFIER MODULES / INSTALLED | Y9: =#REF!+#REF! -> #REF! | AE9: =#REF! -> #REF!
C10: 3) RECTIFIER MODULE RATING, WATTS / AMPS | Y10: =#REF! -> #REF! | AE10: =#REF! -> #REF!
C11: 4) BATTERY BRAND / VOLTAGE RATING | Y11: =#REF! -> #REF! | AE11: =#REF! -> #REF!
C12: 5) NUMBER OF BATTERIES in BANKS / CAPACITY per CELL (AH) | Y12: =#REF! -> #REF! | AE12: =#REF! -> #REF!
C13: 6) PRESENT LOAD READING, PANEL DISPLAY / CLAMP METER (A) | Y13: =#REF! -> #REF! | AE13: Ampere
C14: 7) RECTIFIER MODULES IN OPERATION | Y14: =#REF! -> #REF! | AE14: modules
C15: 8) ACTUAL FLOAT VOLTAGE (V) | Y15: =#REF! -> #REF! | AE15: Voltage
B17: C7.2. PROPOSED PDU/DCDU RECTIFIER LOAD SCHEDULE
D18: PROPOSED ADDITIONAL LOAD(S)
D19: Load No | G19: Equipment Type (Load Description) | O19: Power Rating (Watts) | S19: Current Rating (Amps) | W19: Cable Size (AWG) | Z19: Circuit Breaker Rating (Amps) | AE19: Deployment Remarks
D21: 1 | AL21: Power rating Autofill
D22: 2
D23: 3
D24: 4
D25: 5
D26: 6
D27: 7
D28: TOTAL: | S28: =(SUM(S21:V27)) -> 0
D30: Total Full Load Current = | L30: Existing Load + Proposed Load (100% of Rated Load) = | Z30: =Y13+S28 -> #REF! | AD30: Amps
G31: Existing Rectifier Capacity: | P31: No. Modules x Ampere Capacity | Y31: = | Z31: =Y14*AE10 -> #REF! | AD31: Amps
G32: Existing Battery Capacity: | P32: No. of Batt Banks x Batt Capacity | Y32: = | Z32: =Y12*AE12 -> #REF! | AD32: AH
C34: RECTIFIER SUFFICIENCY COMPUTATION:
C36: Available Rectifier Capacity = | L36: Existing Rectifier Capacity - (Total Full Load Current) - (10% of Battery Capacity)
L37: - Rectifier Module Current Rating
C38: Available Rectifier Capacity = | L38: =Z31 -> #REF! | O38: Amps - | R38: =Z30 -> #REF! | U38: Amps - | X38: ( | Y38: =Z32 -> #REF! | AA38: * | AB38: 0.05) | AD38: - | AE38: =AE10 -> #REF! | AH38: Amps | AL38: 179.78 Amps - 67.99 Amps - (400*0.1) - 44.94 Amps
C39: Available Rectifier Capacity = | L39: =Z31-Z30-(Z32*0.05)-AE10 -> #REF! | Q39: Amperes | T39: (if result value is negative, provision of additional module is required)
C40: Percent Utilization (TLC/Existing Rectifier Capacity) | R40: = | S40: =Z30/Z31 -> #REF! | AL40: If % utilization is >59% add module
C42: BATTERY BACK-UP TIME COMPUTATION:
C44: BBUT = | F44: BATTERY CAPACITY (AMPERE-HOUR) / FUTURE TOTAL LOAD (AMPERE)
C45: BBUT = | F45: =Z32/Z30 -> #REF! | I45: Hours
B47: C7.3. END-STATE SUFFICIENCY COMPUTATION: | R47: (applicable only if there will be new Rectifier System or Upgraded Module)
C49: Available Rectifier Capacity = | L49: (Future Rectifier Capacity - (Total Full Load Current) - (10% of Battery Capacity)
L50: - Rectifier Module Current Rating | AK50: 37.45 | AL50: 7 | AM50: =AK50*AL50 -> 262.15
...

Sheet C RC-FE (proposed)
H2: ='RS4-computation (existing)'!H2:AD2 -> #REF!
H3: Technical Site Survey Report
H4: Site Name | M4: ='RS4-computation (existing)'!M4:AD4 -> #REF!
H5: PLA ID | M5: ='RS4-computation (existing)'!M5:AD5 -> #REF!
B6: C8. Proposed Rectifer Computation
B7: C8.1. PROPOSED RECTIFIER
C8: 1) EXISTING RECTIFIER SYSTEM BRAND - MODEL
C9: 2) MAXIMUM RECTIFIER MODULES / INSTALLED
C10: 3) RECTIFIER MODULE RATING, WATTS / AMPS
C11: 4) BATTERY BRAND / VOLTAGE RATING
C12: 5) NUMBER OF BATTERIES in BANKS / CAPACITY per CELL (AH)
C13: 6) PRESENT LOAD READING, PANEL DISPLAY / CLAMP METER (A) | AE13: Ampere
C14: 7) RECTIFIER MODULES IN OPERATION | AE14: modules
C15: 8) ACTUAL FLOAT VOLTAGE (V) | AE15: Voltage
B17: C8.2. PROPOSED PDU/DCDU RECTIFIER LOAD SCHEDULE
D18: PROPOSED ADDITIONAL LOAD(S)
D19: Load No | G19: Equipment Type (Load Description) | O19: Power Rating (Watts) | S19: Current Rating (Amps) | W19: Cable Size (AWG) | Z19: Circuit Breaker Rating (Amps) | AE19: Remarks
D21: 1 | AL21: Power rating Autofill
D22: 2
D23: 3
D24: 4
D25: 5
D26: 6
D27: 7
D28: TOTAL: | S28: =SUM(S21:V27) -> 0
D30: Total Full Load Current = | L30: Existing Load + Proposed Load (100% of Rated Load) = | Z30: =Y13+S28 -> 0 | AD30: Amps
G31: Existing Rectifier Capacity: | P31: No. Modules x Ampere Capacity | Y31: = | Z31: =Y14*AE10 -> 0 | AD31: Amps
G32: Existing Battery Capacity: | P32: No. of Batt Banks x Batt Capacity | Y32: = | Z32: =Y12*AE12 -> 0 | AD32: AH
C34: RECTIFIER SUFFICIENCY COMPUTATION:
C36: Available Rectifier Capacity = | L36: Existing Rectifier Capacity - (Total Full Load Current) - (10% of Battery Capacity)
L37: - Rectifier Module Current Rating
C38: Available Rectifier Capacity = | L38: =Z31 -> 0 | O38: Amps - | R38: =Z30 -> 0 | U38: Amps - | X38: ( | Y38: =Z32 -> 0 | AA38: * | AB38: 0.1) | AD38: - | AE38: =AE10 -> 0 | AH38: Amps | AL38: 179.78 Amps - 67.99 Amps - (400*0.1) - 44.94 Amps
C39: Available Rectifier Capacity = | L39: =Z31-Z30-(Z32*0.1)-AE10 -> 0 | Q39: Amperes | T39: (if result value is negative, provision of additional module is required)
C40: Percent Utilization (TLC/Existing Rectifier Capacity) | R40: = | S40: =Z30/Z31 -> #DIV/0! | AL40: If % utilization is >59% add module
C42: BATTERY BACK-UP TIME COMPUTATION:
C44: BBUT = | F44: BATTERY CAPACITY (AMPERE-HOUR) / FUTURE TOTAL LOAD (AMPERE)
C45: BBUT = | F45: =Z32/Z30 -> #DIV/0! | I45: Hours
B47: C8.3. END-STATE SUFFICIENCY COMPUTATION: | R47: (applicable only if there will be new Rectifier System or Upgraded Module)
C49: Available Rectifier Capacity = | L49: (Future Rectifier Capacity - (Total Full Load Current) - (10% of Battery Capacity)
L50: - Rectifier Module Current Rating | AL50: 7 | AM50: =AK50*AL50 -> 0
...

Sheet sketch-drawings On site
B4: 1.WHOLE SITE SKETCH-DRAWINGS | H4: Drawing File Name : | J4: =#REF!&"-"&#REF! -> #REF!
B37: 2.CABIN SKETCH-DRAWINGS ON SITE | H37: Drawing File Name : | J37: =J4 -> #REF!
B70: 3. CABLE ROUTING(ESPECIALLY ROOFTOP SITE) | H70: Drawing File Name : | J70: =J37 -> #REF!

Sheet RS2-computation (existing) (2)
H2: =#REF! -> #REF!
H3: Technical Site Survey Report
H4: Site Name | M4: =#REF! -> #REF!
H5: PLA ID | M5: =#REF! -> #REF!
B6: C7. Rectifer1 Computation
B7: C7.1. EXISTING RECTIFIER
C8: 1) EXISTING RECTIFIER SYSTEM BRAND - MODEL | Y8: EMERSON
C9: 2) MAXIMUM RECTIFIER MODULES / INSTALLED | Y9: =#REF!+#REF! -> #REF! | AE9: =#REF! -> #REF!
C10: 3) RECTIFIER MODULE RATING, WATTS / AMPS | Y10: =#REF! -> #REF! | AE10: =#REF! -> #REF!
C11: 4) BATTERY BRAND / VOLTAGE RATING | Y11: =#REF! -> #REF! | AE11: 12
C12: 5) NUMBER OF BATTERIES in BANKS / CAPACITY per CELL (AH) | Y12: 1 | AE12: 150
C13: 6) PRESENT LOAD READING, PANEL DISPLAY / CLAMP METER (A) | Y13: 33.1 | AE13: Ampere
C14: 7) RECTIFIER MODULES IN OPERATION | Y14: =#REF! -> #REF! | AE14: modules
C15: 8) ACTUAL FLOAT VOLTAGE (V) | Y15: 53.5 | AE15: Voltage
B17: C7.2. PROPOSED PDU/DCDU RECTIFIER LOAD SCHEDULE
D18: PROPOSED ADDITIONAL LOAD(S)
D19: Load No | G19: Equipment Type (Load Description) | O19: Power Rating (Watts) | S19: Current Rating (Amps) | W19: Cable Size (AWG) | Z19: Circuit Breaker Rating (Amps) | AE19: Deployment Remarks
D21: 1 | G21: NOKIA OLT MF-2 | O21: 450 | S21: 7.5 | Z21: 16 | AL21: Power rating Autofill
D22: 2
D23: 3
D24: 4 | AL24: FRPA | AM24: 934
D25: 5 | AL25: FHPD | AM25: 1203
D26: 6 | AL26: FXED | AM26: 1272
D27: 7 | AL27: FHEL | AM27: 1353
D28: TOTAL: | S28: =(SUM(S21:V27)) -> 7.5 | AL28: AZNA | AM28: 1272
AL29: AZHA | AM29: 1338
D30: Total Full Load Current = | L30: Existing Load + Proposed Load (100% of Rated Load) = | Z30: =Y13+S28 -> 40.6 | AD30: Amps | AL30: MIMO26N | AM30: 1300
G31: Existing Rectifier Capacity: | P31: No. Modules x Ampere Capacity | Y31: = | Z31: =Y14*AE10 -> #REF! | AD31: Amps
G32: Existing Battery Capacity: | P32: No. of Batt Banks x Batt Capacity | Y32: = | Z32: =Y12*AE12 -> 150 | AD32: AH
C34: RECTIFIER SUFFICIENCY COMPUTATION:
C36: Available Rectifier Capacity = | L36: Existing Rectifier Capacity - (Total Full Load Current) - (10% of Battery Capacity)
L37: - Rectifier Module Current Rating
C38: Available Rectifier Capacity = | L38: =Z31 -> #REF! | O38: Amps - | R38: =Z30 -> 40.6 | U38: Amps - | X38: ( | Y38: =Z32 -> 150 | AA38: * | AB38: 0.05) | AD38: - | AE38: =AE10 -> #REF! | AH38: Amps | AL38: 179.78 Amps - 67.99 Amps - (400*0.1) - 44.94 Amps
C39: Available Rectifier Capacity = | L39: =Z31-Z30-(Z32*0.05)-AE10 -> #REF! | Q39: Amperes | T39: (if result value is negative, provision of additional module is required)
C40: Percent Utilization (TLC/Existing Rectifier Capacity) | R40: = | S40: =Z30/Z31 -> #REF! | AL40: If % utilization is >59% add module
C42: BATTERY BACK-UP TIME COMPUTATION:
C44: BBUT = | F44: BATTERY CAPACITY (AMPERE-HOUR) / FUTURE TOTAL LOAD (AMPERE)
C45: BBUT = | F45: =Z32/Z30 -> 3.6945813 | I45: Hours
B47: C7.3. END-STATE SUFFICIENCY COMPUTATION: | R47: (applicable only if there will be new Rectifier System or Upgraded Module)
C49: Available Rectifier Capacity = | L49: (Future Rectifier Capacity - (Total Full Load Current) - (10% of Battery Capacity)
...

Sheet RS2-computation (existing)
H2: =#REF! -> #REF!
H3: Technical Site Survey Report
H4: Site Name | M4: =#REF! -> #REF!
H5: PLA ID | M5: =#REF! -> #REF!
B6: C7. Rectifer2 Computation
B7: C7.1. EXISTING RECTIFIER
C8: 1) EXISTING RECTIFIER SYSTEM BRAND - MODEL | Y8: =#REF! -> #REF!
C9: 2) MAXIMUM RECTIFIER MODULES / INSTALLED | Y9: =#REF!+#REF! -> #REF! | AE9: =#REF! -> #REF!
C10: 3) RECTIFIER MODULE RATING, WATTS / AMPS | Y10: =#REF! -> #REF! | AE10: =#REF! -> #REF!
C11: 4) BATTERY BRAND / VOLTAGE RATING | Y11: =#REF! -> #REF! | AE11: =#REF! -> #REF!
C12: 5) NUMBER OF BATTERIES in BANKS / CAPACITY per CELL (AH) | Y12: =#REF! -> #REF! | AE12: =#REF! -> #REF!
C13: 6) PRESENT LOAD READING, PANEL DISPLAY / CLAMP METER (A) | Y13: =#REF! -> #REF! | AE13: Ampere
C14: 7) RECTIFIER MODULES IN OPERATION | Y14: =#REF! -> #REF! | AE14: modules
C15: 8) ACTUAL FLOAT VOLTAGE (V) | Y15: =#REF! -> #REF! | AE15: Voltage
B17: C7.2. PROPOSED PDU/DCDU RECTIFIER LOAD SCHEDULE
D18: PROPOSED ADDITIONAL LOAD(S)
D19: Load No | G19: Equipment Type (Load Description) | O19: Power Rating (Watts) | S19: Current Rating (Amps) | W19: Cable Size (AWG) | Z19: Circuit Breaker Rating (Amps) | AE19: Deployment Remarks
D21: 1 | G21: NOKIA OLT FX-4 | O21: 515 | S21: 7.5 | Z21: 16 | AE21: OPTION 1 | AL21: Power rating Autofill
D22: 2 | G22: NOKIA OLT FX-4 + RS ODC | Z22: 20 | AE22: OPTION 2
D23: 3
D24: 4
D25: 5
D26: 6
D27: 7
D28: TOTAL: | S28: =(SUM(S21:V27)) -> 7.5
D30: Total Full Load Current = | L30: Existing Load + Proposed Load (100% of Rated Load) = | Z30: =Y13+S28 -> #REF! | AD30: Amps
G31: Existing Rectifier Capacity: | P31: No. Modules x Ampere Capacity | Y31: = | Z31: =Y14*AE10 -> #REF! | AD31: Amps
G32: Existing Battery Capacity: | P32: No. of Batt Banks x Batt Capacity | Y32: = | Z32: =Y12*AE12 -> #REF! | AD32: AH
C34: RECTIFIER SUFFICIENCY COMPUTATION:
C36: Available Rectifier Capacity = | L36: Existing Rectifier Capacity - (Total Full Load Current) - (10% of Battery Capacity)
L37: - Rectifier Module Current Rating
C38: Available Rectifier Capacity = | L38: =Z31 -> #REF! | O38: Amps - | R38: =Z30 -> #REF! | U38: Amps - | X38: ( | Y38: =Z32 -> #REF! | AA38: * | AB38: 0.05) | AD38: - | AE38: =AE10 -> #REF! | AH38: Amps | AL38: 179.78 Amps - 67.99 Amps - (400*0.1) - 44.94 Amps
C39: Available Rectifier Capacity = | L39: =Z31-Z30-(Z32*0.05)-AE10 -> #REF! | Q39: Amperes | T39: (if result value is negative, provision of additional module is required)
C40: Percent Utilization (TLC/Existing Rectifier Capacity) | R40: = | S40: =Z30/Z31 -> #REF! | AL40: If % utilization is >59% add module
C42: BATTERY BACK-UP TIME COMPUTATION:
C44: BBUT = | F44: BATTERY CAPACITY (AMPERE-HOUR) / FUTURE TOTAL LOAD (AMPERE)
